# node

记得为每一个 promise 加上错误处理或者拒绝的处理函数, 另外 Promise.race 如果传空数组将永远不会决议.
catch 只接受一个回调参数, catch:
```
.catch(() => {

});

相当于:

.then(null, () => {

});
```
需要注意, 如果你将一个变量赋值为一个 promise 链, 那么这个变量的 promsie 是最后一个 promise 节点.另外你可以在 promise 链的最后添加一个 catch, 这样前面的错误会一个接一个
地传递下来, 但是需要注意的是, 如果在前面的节点对错误进行了处理, 那么最后的 catch 回调将不会起作用.也就是:
```
const p = new Promise((resolve, reject) => {
  resolve();
})
.then(() => {
  console.log(foo);  // 这里会报错, foo 未定义
})
.then((res) => {
  console.log('nerver');
}, (err) => {
  console.log('err', err); // 会在这里打印出来, 因为这里添加了 reject 态的处理
})
.catch((err) => {
  console.log('catch:', err); // 这里打印不出来 err , 因为前面已经有处理函数处理了
});
```